[{"name": "test.test_linear_regression.LinearRegression.test_calls", "status": "passed", "message": "", "passed": true, "points": ["p05-10.1"], "backtrace": []}, {"name": "test.test_linear_regression.LinearRegression.test_first", "status": "passed", "message": "", "passed": true, "points": ["p05-10.1"], "backtrace": []}, {"name": "test.test_linear_regression.LinearRegression.test_output", "status": "passed", "message": "", "passed": true, "points": ["p05-10.1"], "backtrace": []}, {"name": "test.test_linear_regression.LinearRegression.test_plot", "status": "failed", "message": "Expected 'show' to have been called once. Called 0 times.", "passed": false, "points": ["p05-10.2"], "backtrace": ["  File \"/home/phyu/anaconda3/lib/python3.11/unittest/case.py\", line 57, in testPartExecutor\n    yield\n", "  File \"/home/phyu/anaconda3/lib/python3.11/unittest/case.py\", line 623, in run\n    self._callTestMethod(testMethod)\n", "  File \"/home/phyu/anaconda3/lib/python3.11/unittest/case.py\", line 579, in _callTestMethod\n    if method() is not None:\n       ^^^^^^^^\n", "  File \"/home/phyu/mooc/dap/mooc-data-analysis-with-python-2024-2025/part05-e10_linear_regression/test/test_linear_regression.py\", line 47, in test_plot\n    pshow.assert_called_once()\n", "  File \"/home/phyu/anaconda3/lib/python3.11/unittest/mock.py\", line 918, in assert_called_once\n    raise AssertionError(msg)\n"]}]